<?xml version="1.0" ?>
<mujoco model="go2_human_follow">
  <compiler angle="radian" meshdir="unitree_go2/assets" autolimits="true"/>

  <option timestep="0.005" cone="elliptic" impratio="100" gravity="0 0 -9.81"/>

  <visual>
    <map force="0.1" zfar="30"/>
    <rgba haze="0.15 0.25 0.35 1"/>
    <global offwidth="2560" offheight="1440" elevation="-20" azimuth="120"/>
  </visual>

  <statistic center="0 0 0.7"/>

  <asset>
    <!-- 人体材质 -->
    <texture type="skybox" builtin="gradient" rgb1=".3 .5 .7" rgb2="0 0 0" width="32" height="512"/>
    <texture name="body" type="cube" builtin="flat" mark="cross" width="128" height="128" rgb1="0.8 0.6 0.4" rgb2="0.8 0.6 0.4" markrgb="1 1 1"/>
    <material name="body" texture="body" texuniform="true" rgba="0.8 0.6 .4 1"/>
    <texture name="grid" type="2d" builtin="checker" width="512" height="512" rgb1=".1 .2 .3" rgb2=".2 .3 .4"/>
    <material name="grid" texture="grid" texrepeat="1 1" texuniform="true" reflectance=".2"/>

    <!-- Go2材质 -->
    <material name="metal" rgba=".9 .95 .95 1"/>
    <material name="black" rgba="0 0 0 1"/>
    <material name="white" rgba="1 1 1 1"/>
    <material name="gray" rgba="0.671705 0.692426 0.774270 1"/>

    <!-- Go2网格文件 -->
    <mesh file="base_0.obj"/>
    <mesh file="base_1.obj"/>
    <mesh file="base_2.obj"/>
    <mesh file="base_3.obj"/>
    <mesh file="base_4.obj"/>
    <mesh file="hip_0.obj"/>
    <mesh file="hip_1.obj"/>
    <mesh file="thigh_0.obj"/>
    <mesh file="thigh_1.obj"/>
    <mesh file="thigh_mirror_0.obj"/>
    <mesh file="thigh_mirror_1.obj"/>
    <mesh file="calf_0.obj"/>
    <mesh file="calf_1.obj"/>
    <mesh file="calf_mirror_0.obj"/>
    <mesh file="calf_mirror_1.obj"/>
    <mesh file="foot.obj"/>
  </asset>

  <default>
    <!-- 人体默认设置 -->
    <motor ctrlrange="-1 1" ctrllimited="true"/>
    <default class="human_body">
      <geom type="capsule" condim="3" friction="0.9 0.05 0.1" solimp=".9 .99 .003" solref=".015 1" material="body" group="1"/>
      <default class="thigh">
        <geom size=".06"/>
      </default>
      <default class="shin">
        <geom fromto="0 0 0 0 0 -.3"  size=".049"/>
      </default>
      <default class="foot">
        <geom size=".027"/>
        <default class="foot1">
          <geom fromto="-.07 -.01 0 .14 -.03 0"/>
        </default>
        <default class="foot2">
          <geom fromto="-.07 .01 0 .14  .03 0"/>
        </default>
      </default>
      <default class="arm_upper">
        <geom size=".04"/>
      </default>
      <default class="arm_lower">
        <geom size=".031"/>
      </default>
      <default class="hand">
        <geom type="sphere" size=".04"/>
      </default>
      <joint type="hinge" damping=".2" stiffness="1" armature=".01" limited="true" solimplimit="0 .99 .01"/>
      <default class="joint_big">
        <joint damping="5" stiffness="10"/>
        <default class="hip_x">
          <joint range="-30 10"/>
        </default>
        <default class="hip_z">
          <joint range="-60 35"/>
        </default>
        <default class="hip_y">
          <joint axis="0 1 0" range="-150 20"/>
        </default>
        <default class="joint_big_stiff">
          <joint stiffness="20"/>
        </default>
      </default>
      <default class="knee">
        <joint pos="0 0 .02" axis="0 -1 0" range="-160 2"/>
      </default>
      <default class="ankle">
        <joint range="-50 50"/>
        <default class="ankle_y">
          <joint pos="0 0 .08" axis="0 1 0" stiffness="6"/>
        </default>
        <default class="ankle_x">
          <joint pos="0 0 .04" stiffness="3"/>
        </default>
      </default>
      <default class="shoulder">
        <joint range="-85 60"/>
      </default>
      <default class="elbow">
        <joint range="-100 50" stiffness="0"/>
      </default>
    </default>

    <!-- Go2默认设置 -->
    <default class="go2">
      <geom friction="0.6" margin="0.001" condim="1"/>
      <joint axis="0 1 0" damping="2" armature="0.01" frictionloss="0.2"/>
      <motor ctrlrange="-23.7 23.7"/>
      <default class="go2_abduction">
        <joint axis="1 0 0" range="-1.0472 1.0472"/>
      </default>
      <default class="go2_hip">
        <default class="go2_front_hip">
          <joint range="-1.5708 3.4907"/>
        </default>
        <default class="go2_back_hip">
          <joint range="-0.5236 4.5379"/>
        </default>
      </default>
      <default class="go2_knee">
        <joint range="-2.7227 -0.83776"/>
        <motor ctrlrange="-45.43 45.43"/>
      </default>
      <default class="go2_visual">
        <geom type="mesh" contype="0" conaffinity="0" group="2"/>
      </default>
      <default class="go2_collision">
        <geom group="3"/>
        <default class="go2_foot">
          <geom size="0.022" pos="-0.002 0 -0.213" priority="1" solimp="0.015 1 0.022" condim="6"
            friction="0.8 0.02 0.01"/>
        </default>
      </default>
    </default>
  </default>

  <worldbody>
    <!-- 地面 -->
    <geom name="floor" size="0 0 .05" type="plane" material="grid" condim="3"/>

    <!-- 灯光 -->
    <light name="spotlight" mode="targetbodycom" target="human" diffuse=".8 .8 .8" specular="0.3 0.3 0.3" pos="0 -6 4" cutoff="30"/>
    <light name="top" pos="0 0 2" mode="trackcom"/>

    <!-- 人体模型 -->
    <body name="human" pos="3 0 0" childclass="human_body">
      <camera name="human_back" pos="-3 0 1" xyaxes="0 -1 0 1 0 2" mode="trackcom"/>
      <camera name="human_side" pos="0 -3 1" xyaxes="1 0 0 0 1 2" mode="trackcom"/>
      <freejoint name="human_root"/>
      <geom name="torso" fromto="0 -.07 0 0 .07 0" size=".07"/>
      <geom name="waist_upper" fromto="-.01 -.06 -.12 -.01 .06 -.12" size=".06"/>
      <body name="head" pos="0 0 .19">
        <geom name="head" type="sphere" size=".09"/>
        <camera name="human_egocentric" pos=".09 0 0" xyaxes="0 -1 0 .1 0 1" fovy="80"/>
      </body>
      <body name="waist_lower" pos="-.01 0 -.26">
        <geom name="waist_lower" fromto="0 -.06 0 0 .06 0" size=".06"/>
        <joint name="abdomen_z" pos="0 0 .065" axis="0 0 1" range="-45 45" class="joint_big_stiff"/>
        <joint name="abdomen_y" pos="0 0 .065" axis="0 1 0" range="-75 30" class="joint_big"/>
        <body name="pelvis" pos="0 0 -.165">
          <joint name="abdomen_x" pos="0 0 .1" axis="1 0 0" range="-35 35" class="joint_big"/>
          <geom name="butt" fromto="-.02 -.07 0 -.02 .07 0" size=".09"/>
          <body name="thigh_right" pos="0 -.1 -.04">
            <joint name="hip_x_right" axis="1 0 0" class="hip_x"/>
            <joint name="hip_z_right" axis="0 0 1" class="hip_z"/>
            <joint name="hip_y_right" class="hip_y"/>
            <geom name="thigh_right" fromto="0 0 0 0 .01 -.34" class="thigh"/>
            <body name="shin_right" pos="0 .01 -.4">
              <joint name="knee_right" class="knee"/>
              <geom name="shin_right" class="shin"/>
              <body name="foot_right" pos="0 0 -.39">
                <joint name="ankle_y_right" class="ankle_y"/>
                <joint name="ankle_x_right" class="ankle_x" axis="1 0 .5"/>
                <geom name="foot1_right" class="foot1"/>
                <geom name="foot2_right" class="foot2"/>
              </body>
            </body>
          </body>
          <body name="thigh_left" pos="0 .1 -.04">
            <joint name="hip_x_left" axis="-1 0 0" class="hip_x"/>
            <joint name="hip_z_left" axis="0 0 -1" class="hip_z"/>
            <joint name="hip_y_left" class="hip_y"/>
            <geom name="thigh_left" fromto="0 0 0 0 -.01 -.34" class="thigh"/>
            <body name="shin_left" pos="0 -.01 -.4">
              <joint name="knee_left" class="knee"/>
              <geom name="shin_left" fromto="0 0 0 0 0 -.3" class="shin"/>
              <body name="foot_left" pos="0 0 -.39">
                <joint name="ankle_y_left" class="ankle_y"/>
                <joint name="ankle_x_left" class="ankle_x" axis="-1 0 -.5"/>
                <geom name="foot1_left" class="foot1"/>
                <geom name="foot2_left" class="foot2"/>
              </body>
            </body>
          </body>
        </body>
      </body>
      <body name="upper_arm_right" pos="0 -.17 .06">
        <joint name="shoulder1_right" axis="2 1 1"  class="shoulder"/>
        <joint name="shoulder2_right" axis="0 -1 1" class="shoulder"/>
        <geom name="upper_arm_right" fromto="0 0 0 .16 -.16 -.16" class="arm_upper"/>
        <body name="lower_arm_right" pos=".18 -.18 -.18">
          <joint name="elbow_right" axis="0 -1 1" class="elbow"/>
          <geom name="lower_arm_right" fromto=".01 .01 .01 .17 .17 .17" class="arm_lower"/>
          <body name="hand_right" pos=".18 .18 .18">
            <geom name="hand_right" zaxis="1 1 1" class="hand"/>
          </body>
        </body>
      </body>
      <body name="upper_arm_left" pos="0 .17 .06">
        <joint name="shoulder1_left" axis="-2 1 -1" class="shoulder"/>
        <joint name="shoulder2_left" axis="0 -1 -1"  class="shoulder"/>
        <geom name="upper_arm_left" fromto="0 0 0 .16 .16 -.16" class="arm_upper"/>
        <body name="lower_arm_left" pos=".18 .18 -.18">
          <joint name="elbow_left" axis="0 -1 -1" class="elbow"/>
          <geom name="lower_arm_left" fromto=".01 -.01 .01 .17 -.17 .17" class="arm_lower"/>
          <body name="hand_left" pos=".18 -.18 .18">
            <geom name="hand_left" zaxis="1 -1 1" class="hand"/>
          </body>
        </body>
      </body>
    </body>

    <!-- Go2机器人模型 -->
    <body name="robot" pos="0 0 0.445" childclass="go2">
      <inertial pos="0.021112 0 -0.005366" quat="-0.000543471 0.713435 -0.00173769 0.700719" mass="6.921"
        diaginertia="0.107027 0.0980771 0.0244531"/>
      <freejoint name="robot_root"/>
      <geom mesh="base_0" material="black" class="go2_visual"/>
      <geom mesh="base_1" material="black" class="go2_visual"/>
      <geom mesh="base_2" material="black" class="go2_visual"/>
      <geom mesh="base_3" material="white" class="go2_visual"/>
      <geom mesh="base_4" material="gray" class="go2_visual"/>
      <geom size="0.1881 0.04675 0.057" type="box" class="go2_collision"/>
      <geom size="0.05 0.045" pos="0.285 0 0.01" type="cylinder" class="go2_collision"/>
      <geom size="0.047" pos="0.293 0 -0.06" class="go2_collision"/>
      <site name="imu" pos="-0.02557 0 0.04232"/>
      
      <!-- ✅ Go2 机器人头部摄像头（新增） -->
      <camera name="go2_head" pos="0.15 0 0.12" xyaxes="0 -1 0 0 0 1" fovy="90" mode="trackcom"/>
      
      <body name="FL_hip" pos="0.1934 0.0465 0">
        <inertial pos="-0.0054 0.00194 -0.000105" quat="0.497014 0.499245 0.505462 0.498237" mass="0.678"
          diaginertia="0.00088403 0.000596003 0.000479967"/>
        <joint name="FL_hip_joint" class="go2_abduction"/>
        <geom mesh="hip_0" material="metal" class="go2_visual"/>
        <geom mesh="hip_1" material="gray" class="go2_visual"/>
        <geom size="0.046 0.02" pos="0 0.08 0" quat="1 1 0 0" type="cylinder" class="go2_collision"/>
        <body name="FL_thigh" pos="0 0.0955 0">
          <inertial pos="-0.00374 -0.0223 -0.0327" quat="0.829533 0.0847635 -0.0200632 0.551623" mass="1.152"
            diaginertia="0.00594973 0.00584149 0.000878787"/>
          <joint name="FL_thigh_joint" class="go2_front_hip"/>
          <geom mesh="thigh_0" material="metal" class="go2_visual"/>
          <geom mesh="thigh_1" material="gray" class="go2_visual"/>
          <geom size="0.1065 0.01225 0.017" pos="0 0 -0.1065" quat="0.707107 0 0.707107 0" type="box" class="go2_collision"/>
          <body name="FL_calf" pos="0 0 -0.213">
            <inertial pos="0.00629595 -0.000622121 -0.141417" quat="0.710672 0.00154099 -0.00450087 0.703508"
              mass="0.241352" diaginertia="0.0014901 0.00146356 5.31397e-05"/>
            <joint name="FL_calf_joint" class="go2_knee"/>
            <geom mesh="calf_0" material="gray" class="go2_visual"/>
            <geom mesh="calf_1" material="black" class="go2_visual"/>
            <geom size="0.012 0.06" pos="0.008 0 -0.06" quat="0.994493 0 -0.104807 0" type="cylinder" class="go2_collision"/>
            <geom size="0.011 0.0325" pos="0.02 0 -0.148" quat="0.999688 0 0.0249974 0" type="cylinder" class="go2_collision"/>
            <geom pos="0 0 -0.213" mesh="foot" class="go2_visual" material="black"/>
            <geom name="FL" class="go2_foot"/>
          </body>
        </body>
      </body>
      <body name="FR_hip" pos="0.1934 -0.0465 0">
        <inertial pos="-0.0054 -0.00194 -0.000105" quat="0.498237 0.505462 0.499245 0.497014" mass="0.678"
          diaginertia="0.00088403 0.000596003 0.000479967"/>
        <joint name="FR_hip_joint" class="go2_abduction"/>
        <geom mesh="hip_0" material="metal" class="go2_visual" quat="4.63268e-05 1 0 0"/>
        <geom mesh="hip_1" material="gray" class="go2_visual" quat="4.63268e-05 1 0 0"/>
        <geom size="0.046 0.02" pos="0 -0.08 0" quat="0.707107 0.707107 0 0" type="cylinder" class="go2_collision"/>
        <body name="FR_thigh" pos="0 -0.0955 0">
          <inertial pos="-0.00374 0.0223 -0.0327" quat="0.551623 -0.0200632 0.0847635 0.829533" mass="1.152"
            diaginertia="0.00594973 0.00584149 0.000878787"/>
          <joint name="FR_thigh_joint" class="go2_front_hip"/>
          <geom mesh="thigh_mirror_0" material="metal" class="go2_visual"/>
          <geom mesh="thigh_mirror_1" material="gray" class="go2_visual"/>
          <geom size="0.1065 0.01225 0.017" pos="0 0 -0.1065" quat="0.707107 0 0.707107 0" type="box" class="go2_collision"/>
          <body name="FR_calf" pos="0 0 -0.213">
            <inertial pos="0.00629595 0.000622121 -0.141417" quat="0.703508 -0.00450087 0.00154099 0.710672"
              mass="0.241352" diaginertia="0.0014901 0.00146356 5.31397e-05"/>
            <joint name="FR_calf_joint" class="go2_knee"/>
            <geom mesh="calf_mirror_0" material="gray" class="go2_visual"/>
            <geom mesh="calf_mirror_1" material="black" class="go2_visual"/>
            <geom size="0.013 0.06" pos="0.01 0 -0.06" quat="0.995004 0 -0.0998334 0" type="cylinder" class="go2_collision"/>
            <geom size="0.011 0.0325" pos="0.02 0 -0.148" quat="0.999688 0 0.0249974 0" type="cylinder" class="go2_collision"/>
            <geom pos="0 0 -0.213" mesh="foot" class="go2_visual" material="black"/>
            <geom name="FR" class="go2_foot"/>
          </body>
        </body>
      </body>
      <body name="RL_hip" pos="-0.1934 0.0465 0">
        <inertial pos="0.0054 0.00194 -0.000105" quat="0.505462 0.498237 0.497014 0.499245" mass="0.678"
          diaginertia="0.00088403 0.000596003 0.000479967"/>
        <joint name="RL_hip_joint" class="go2_abduction"/>
        <geom mesh="hip_0" material="metal" class="go2_visual" quat="4.63268e-05 0 1 0"/>
        <geom mesh="hip_1" material="gray" class="go2_visual" quat="4.63268e-05 0 1 0"/>
        <geom size="0.046 0.02" pos="0 0.08 0" quat="0.707107 0.707107 0 0" type="cylinder" class="go2_collision"/>
        <body name="RL_thigh" pos="0 0.0955 0">
          <inertial pos="-0.00374 -0.0223 -0.0327" quat="0.829533 0.0847635 -0.0200632 0.551623" mass="1.152"
            diaginertia="0.00594973 0.00584149 0.000878787"/>
          <joint name="RL_thigh_joint" class="go2_back_hip"/>
          <geom mesh="thigh_0" material="metal" class="go2_visual"/>
          <geom mesh="thigh_1" material="gray" class="go2_visual"/>
          <geom size="0.1065 0.01225 0.017" pos="0 0 -0.1065" quat="0.707107 0 0.707107 0" type="box" class="go2_collision"/>
          <body name="RL_calf" pos="0 0 -0.213">
            <inertial pos="0.00629595 -0.000622121 -0.141417" quat="0.710672 0.00154099 -0.00450087 0.703508"
              mass="0.241352" diaginertia="0.0014901 0.00146356 5.31397e-05"/>
            <joint name="RL_calf_joint" class="go2_knee"/>
            <geom mesh="calf_0" material="gray" class="go2_visual"/>
            <geom mesh="calf_1" material="black" class="go2_visual"/>
            <geom size="0.013 0.06" pos="0.01 0 -0.06" quat="0.995004 0 -0.0998334 0" type="cylinder" class="go2_collision"/>
            <geom size="0.011 0.0325" pos="0.02 0 -0.148" quat="0.999688 0 0.0249974 0" type="cylinder" class="go2_collision"/>
            <geom pos="0 0 -0.213" mesh="foot" class="go2_visual" material="black"/>
            <geom name="RL" class="go2_foot"/>
          </body>
        </body>
      </body>
      <body name="RR_hip" pos="-0.1934 -0.0465 0">
        <inertial pos="0.0054 -0.00194 -0.000105" quat="0.499245 0.497014 0.498237 0.505462" mass="0.678"
          diaginertia="0.00088403 0.000596003 0.000479967"/>
        <joint name="RR_hip_joint" class="go2_abduction"/>
        <geom mesh="hip_0" material="metal" class="go2_visual" quat="2.14617e-09 4.63268e-05 4.63268e-05 -1"/>
        <geom mesh="hip_1" material="gray" class="go2_visual" quat="2.14617e-09 4.63268e-05 4.63268e-05 -1"/>
        <geom size="0.046 0.02" pos="0 -0.08 0" quat="0.707107 0.707107 0 0" type="cylinder" class="go2_collision"/>
        <body name="RR_thigh" pos="0 -0.0955 0">
          <inertial pos="-0.00374 0.0223 -0.0327" quat="0.551623 -0.0200632 0.0847635 0.829533" mass="1.152"
            diaginertia="0.00594973 0.00584149 0.000878787"/>
          <joint name="RR_thigh_joint" class="go2_back_hip"/>
          <geom mesh="thigh_mirror_0" material="metal" class="go2_visual"/>
          <geom mesh="thigh_mirror_1" material="gray" class="go2_visual"/>
          <geom size="0.1065 0.01225 0.017" pos="0 0 -0.1065" quat="0.707107 0 0.707107 0" type="box" class="go2_collision"/>
          <body name="RR_calf" pos="0 0 -0.213">
            <inertial pos="0.00629595 0.000622121 -0.141417" quat="0.703508 -0.00450087 0.00154099 0.710672"
              mass="0.241352" diaginertia="0.0014901 0.00146356 5.31397e-05"/>
            <joint name="RR_calf_joint" class="go2_knee"/>
            <geom mesh="calf_mirror_0" material="gray" class="go2_visual"/>
            <geom mesh="calf_mirror_1" material="black" class="go2_visual"/>
            <geom size="0.013 0.06" pos="0.01 0 -0.06" quat="0.995004 0 -0.0998334 0" type="cylinder" class="go2_collision"/>
            <geom size="0.011 0.0325" pos="0.02 0 -0.148" quat="0.999688 0 0.0249974 0" type="cylinder" class="go2_collision"/>
            <geom pos="0 0 -0.213" mesh="foot" class="go2_visual" material="black"/>
            <geom name="RR" class="go2_foot"/>
          </body>
        </body>
      </body>
    </body>
  </worldbody>

  <contact>
    <exclude body1="waist_lower" body2="thigh_right"/>
    <exclude body1="waist_lower" body2="thigh_left"/>
  </contact>

  <tendon>
    <fixed name="hamstring_right" limited="true" range="-0.3 2">
      <joint joint="hip_y_right" coef=".5"/>
      <joint joint="knee_right" coef="-.5"/>
    </fixed>
    <fixed name="hamstring_left" limited="true" range="-0.3 2">
      <joint joint="hip_y_left" coef=".5"/>
      <joint joint="knee_left" coef="-.5"/>
    </fixed>
  </tendon>

  <actuator>
    <!-- 人体执行器 -->
    <motor name="abdomen_z"       gear="40"  joint="abdomen_z"/>
    <motor name="abdomen_y"       gear="40"  joint="abdomen_y"/>
    <motor name="abdomen_x"       gear="40"  joint="abdomen_x"/>
    <motor name="hip_x_right"     gear="40"  joint="hip_x_right"/>
    <motor name="hip_z_right"     gear="40"  joint="hip_z_right"/>
    <motor name="hip_y_right"     gear="120" joint="hip_y_right"/>
    <motor name="knee_right"      gear="80"  joint="knee_right"/>
    <motor name="ankle_y_right"   gear="20"  joint="ankle_y_right"/>
    <motor name="ankle_x_right"   gear="20"  joint="ankle_x_right"/>
    <motor name="hip_x_left"      gear="40"  joint="hip_x_left"/>
    <motor name="hip_z_left"      gear="40"  joint="hip_z_left"/>
    <motor name="hip_y_left"      gear="120" joint="hip_y_left"/>
    <motor name="knee_left"       gear="80"  joint="knee_left"/>
    <motor name="ankle_y_left"    gear="20"  joint="ankle_y_left"/>
    <motor name="ankle_x_left"    gear="20"  joint="ankle_x_left"/>
    <motor name="shoulder1_right" gear="20"  joint="shoulder1_right"/>
    <motor name="shoulder2_right" gear="20"  joint="shoulder2_right"/>
    <motor name="elbow_right"     gear="40"  joint="elbow_right"/>
    <motor name="shoulder1_left"  gear="20"  joint="shoulder1_left"/>
    <motor name="shoulder2_left"  gear="20"  joint="shoulder2_left"/>
    <motor name="elbow_left"      gear="40"  joint="elbow_left"/>

    <!-- Go2执行器 -->
    <motor class="go2_abduction" name="FL_hip" joint="FL_hip_joint"/>
    <motor class="go2_hip" name="FL_thigh" joint="FL_thigh_joint"/>
    <motor class="go2_knee" name="FL_calf" joint="FL_calf_joint"/>
    <motor class="go2_abduction" name="FR_hip" joint="FR_hip_joint"/>
    <motor class="go2_hip" name="FR_thigh" joint="FR_thigh_joint"/>
    <motor class="go2_knee" name="FR_calf" joint="FR_calf_joint"/>
    <motor class="go2_abduction" name="RL_hip" joint="RL_hip_joint"/>
    <motor class="go2_hip" name="RL_thigh" joint="RL_thigh_joint"/>
    <motor class="go2_knee" name="RL_calf" joint="RL_calf_joint"/>
    <motor class="go2_abduction" name="RR_hip" joint="RR_hip_joint"/>
    <motor class="go2_hip" name="RR_thigh" joint="RR_thigh_joint"/>
    <motor class="go2_knee" name="RR_calf" joint="RR_calf_joint"/>
  </actuator>

  <keyframe>
    <!-- 人体关键帧 -->
    <key name="human_home" qpos="3 0 0.27 1 0 0 0 0 0 0 0 0 0 0 0 0 0 0 0 0 0 0 0 0 0 0 0 0"/>

    <!-- Go2关键帧 -->
    <key name="robot_home" qpos="0 0 0.27 1 0 0 0 0 0.9 -1.8 0 0.9 -1.8 0 0.9 -1.8 0 0.9 -1.8"
      ctrl="0 0.9 -1.8 0 0.9 -1.8 0 0.9 -1.8 0 0.9 -1.8"/>
  </keyframe>
</mujoco>
